Workbook

Sheet SOP
A1: AHD Site Readiness Assessment Tool — SOP and Scoring Guide
H2: This tool was adapted from the 2025 WHO guidelines on Advanced HIV Disease Management and the Cameroon National HIV guidelines (2024)
A3: Purpose and workflow
A4: Use this workbook to assess site readiness for the advanced HIV disease (AHD) package of care. Complete the Facility_Profile and Checklist sheets. Domain 7 OI sub-responses are embedded directly below each parent checklist statement. The Readiness_Dashboard, parent OI totals, and Action_Plan calculate automatically. Evidence should be verified through observation, records, stock documents, staff interviews, referral logs, and DAMA where applicable.
A7: Completion steps
A8: Step | B8: Workbook area | C8: What the assessor enters | D8: What calculates automatically | E8: Quality control | F8: Primary output | G8: Notes
A9: 1 | B9: Facility_Profile | C9: Site identifiers, region, district, assessment date, implementing partner, service entry points, and critical checks. | D9: Facility score summary and readiness status. | F9: Verified facility profile | G9: Assessment date drives recommended action due dates.
A10: 2 | B10: Checklist | C10: Select Yes, Partial, No, or N/A on every scorable checklist line; enter evidence, owner, and manual due date as needed. In Domain 7, complete all six OI lines shown beneath each parent statement. | D10: Ready units, applicable units, gaps, target dates, validation, gap number, question totals, and readiness percentages. | E10: Do not overwrite calculated columns J–Q. | F10: 111 parent questions / 141 scorable response units | G10: Domain 7 parent rows are summaries and are not scored separately.
A11: 3 | B11: Checklist — embedded Domain 7 OI lines | C11: For each of the six Domain 7 parent questions, complete a separate response for toxoplasmosis, Pneumocystis pneumonia, histoplasmosis, chronic diarrhea, oral/esophageal candidiasis, and malnutrition. | D11: Overall and domain-level readiness, completeness, gaps, status, and three high-level dashboard visuals. | E11: Six scoring lines per parent question are required unless an individual condition is documented as N/A. | F11: 36 scorable OI units embedded in the Checklist | G11: Enter responses only on the six OI lines; do not overwrite parent formulas.
A12: 4 | B12: Readiness_Dashboard | C12: Optional priority comments by domain. | D12: Overall and domain-level readiness, completeness, gaps, status, and chart. | E12: Interpret color and text status together; color alone is not the decision rule. | F12: 141 total scorable units | G12: N/A is excluded from the readiness denominator but counts as a completed response.
A13: 5 | B13: Action_Plan | C13: Corrective action, person responsible, due date, status, and verification evidence. | D13: All Partial and No findings from the Checklist | E13: P1 gaps require urgent action and override a high percentage score. | F13: Consolidated gap register | G13: Recommended due dates: P1 30 days, P2 90 days, P3 180 days.
A14: 6 | B14: IP report workbook | C14: Transfer each domain’s applicable units and readiness percentage, plus P1 gaps, N/A, and missing responses. | D14: Weighted site, regional, and national readiness dashboards. | E14: Applicable units + N/A + missing must equal 141 for each site. | F14: Partner reporting dashboard | G14: Use one row per assessed site on the appropriate region sheet.
A17: Scoring methodology
A18: Variable | B18: Location | C18: Allowed values / formula | D18: Numerator contribution | E18: Denominator contribution | F18: Interpretation | G18: User action
A19: Response | B19: Checklist F — all scorable lines | C19: Yes, Partial, No, N/A | D19: Yes = 1; Partial/No = 0; N/A/blank = 0 | E19: Yes/Partial/No = 1; N/A/blank = 0 | F19: Readiness measures the proportion fully ready among applicable assessed units. | G19: Select from dropdown.
A20: Domain 7 parent score | B20: Checklist J–K for parent items 7.1–7.6 | C20: Sum of the six OI scoring lines immediately below each parent question | D20: Number of Yes sub-responses (0–6) | E20: Number of applicable sub-responses (0–6) | F20: Each sub-response contributes equally to its parent question and Domain 7 score. | G20: Complete the six embedded OI lines; do not type over parent formulas.
A21: Readiness % | B21: Dashboard | C21: Ready units ÷ applicable units | D21: Sum of Yes units | E21: Sum of Yes + Partial + No units | F21: N/A is excluded; Partial is not counted as fully ready. | G21: Review by domain and overall.
A22: Data completeness % | B22: Dashboard | C22: (141 − missing responses) ÷ 141 | D22: Completed responses | E22: 141 total response units | F22: N/A counts as completed; blanks are missing. | G22: Complete all blanks before finalizing.
A23: P1 gap | B23: Checklist | C23: P1 item marked Partial or No | D23: — | E23: — | F23: Critical mortality/client-safety readiness risk. | G23: Resolve urgently; P1 gaps override score-based “ready” status.
A24: Recommended target date | B24: Checklist | C24: Assessment date + priority days | D24: — | E24: — | F24: P1 = 30 days; P2 = 90 days; P3 = 180 days. | G24: Use manual due date if a locally agreed date is different.
A27: Performance thresholds and color key
A28: Band | B28: Range / rule | C28: Color | D28: Readiness interpretation | E28: Required management response | F28: P1 rule | G28: Completeness rule
A29: Ready | B29: 90–100% | C29: Green | D29: High readiness. | E29: Maintain, monitor, and close residual noncritical gaps. | F29: No unresolved P1 gaps. | G29: No missing responses.
A30: Substantially ready | B30: 80–89.9% | C30: Yellow | D30: Most requirements are fully ready; targeted improvement remains. | E30: Implement and verify targeted actions. | F30: No unresolved P1 gaps. | G30: No missing responses.
A31: Partially ready | B31: 60–79.9% | C31: Amber | D31: Material readiness gaps remain. | E31: Formal improvement plan, owner, and follow-up required. | F31: No unresolved P1 gaps. | G31: No missing responses.
A32: Critical readiness gap | B32: <60% or any P1 gap | C32: Red | D32: Immediate readiness risk. | E32: Urgent corrective action and escalation. | F32: Any P1 gap makes status critical regardless of score. | G32: Score should not be finalized with missing responses.
A33: Incomplete / no data | B33: Missing responses or no applicable denominator | C33: Gray | D33: Assessment cannot yet be interpreted. | E33: Complete or correct data. | F33: Not assessed until complete. | G33: Missing responses must be zero.
A35: Priority codes
A36: Priority | B36: Risk level | C36: Recommended correction timeframe | D36: Examples | E36: Escalation | F36: Tracking requirement | G36: Status implication
A37: P1 | B37: Critical client-safety or mortality risk | C37: Within 30 days | D37: Absent critical diagnostic/referral/treatment function. | E37: Immediate facility and partner escalation. | F37: Named owner, due date, and verification evidence. | G37: Any unresolved P1 gap = critical status.
A38: P2 | B38: Service reliability or scale-up gap | C38: Within 90 days | D38: Inconsistent availability, incomplete process, or weak coverage. | E38: Review in routine improvement meeting. | F38: Owner and follow-up date required. | G38: Affects percentage-based status.
A39: P3 | B39: Optimization or sustainability action | C39: Within 180 days | D39: Longer-term system strengthening. | E39: Track through routine QI. | F39: Document progress and closure. | G39: Affects percentage-based status.
B41: The workbook contains 111 parent questions and 141 scorable response units. In Domain 7, each parent question is immediately followed by six condition-specific scoring lines; parent totals are summaries and are not scored again.

Sheet Facility_Profile
A1: AHD Site Readiness Assessment Tool
A2: Facility profile, service entry points, critical checks, and automatic score summary
A4: Facility profile and assessment record
A5: Facility / site name | D5: DAMA facility ID / site code
A6: Region | C6: Health district | E6: Facility level
A7: Assessment date | C7: Site tier | E7: Number of clients currently on ART (TX_CURR)
A8: Assessment team / assessor(s) | D8: Implementing partner
A10: Service entry points assessed (drop-down) | B10: Assessed? | D10: Minimum high-priority readiness checks | E10: Ready? | F10: Evidence / comments
A11: HIV testing | D11: AHD identification: rapid CD4 testing (including VISITECT where used) or WHO staging is accessible, documented the same day, and linked to clinical action.
A12: ART clinic | D12: TB screening and diagnosis: symptom screening plus GeneXpert or another WHO-recommended low-complexity automated NAAT, N-POC/NPOC-NAAT where implemented, sample transport, and urine LF-LAM for eligible AHD or seriously ill clients.
A13: TB clinic | D13: Cryptococcal disease: CrAg access, fluconazole/pre-emptive treatment, meningitis referral, lumbar-puncture pathway, and ART-delay SOP.
A14: PMTCT/MCH | D14: Core prophylaxis, treatment, nutrition, and supportive-care commodities are available on site or through a documented referral/resupply pathway.
A15: OPD/emergency | D15: Referral, discharge, early follow-up, missed-visit tracking, and DAMA documentation are active and confidentiality-protected.
A16: Inpatient ward
A17: Pediatric/adolescent clinic
A18: Laboratory
A19: Pharmacy
A20: Community/home-based services
A23: Automatic score summary
A24: Overall readiness % | B24: =Readiness_Dashboard!$B$5 -> 0.5 | D24: P1 gaps | E24: =Readiness_Dashboard!$B$8 -> 1
A25: All gaps | B25: =Readiness_Dashboard!$B$9 -> 1 | D25: Missing responses | E25: =Readiness_Dashboard!$B$10 -> 139
A26: Critical checks status | B26: =IF(COUNTBLANK($E$11:$E$15)>0,"Incomplete",IF(COUNTIF($E$11:$E$15,"No")+COUNTIF($E$11:$E$15,"Partial")>0,"Critical checks unresolved","All critical checks ready")) -> Incomplete | D26: Readiness status | E26: =Readiness_Dashboard!$B$12 -> Incomplete - complete all responses

Sheet Checklist
A1: Facility Preparedness Checklist — 111 Parent Questions / 141 Scorable Response Units (OI sub-responses embedded)
A2: Domain # | B2: Domain | C2: Item no. | D2: Priority level. | E2: Preparedness requirement | F2: Response | G2: Evidence / notes | H2: Person responsible | I2: Proposed deadline | J2: Ready units / score | K2: Applicable units | L2: Gap flag | M2: Priority days | N2: Recommended target date | O2: Validation | P2: Gap # | Q2: Question readiness %
A3: 1 | B3: Governance, service model and accountability | C3: 1.1 | D3: P1 | E3: Facility has a written AHD/OI service SOP aligned with national guidance and current WHO AHD recommendations. | J3: =IF($F3="Yes",1,IF(OR($F3="Partial",$F3="No"),0,"")) | K3: =IF(OR($F3="Yes",$F3="Partial",$F3="No"),1,0) -> 0 | L3: =IF(AND($D3="P1",OR($F3="Partial",$F3="No")),"P1 gap",IF(OR($F3="Partial",$F3="No"),"Gap","")) | M3: =IF($D3="P1",30,IF($D3="P2",90,IF($D3="P3",180,""))) -> 30 | N3: =IF(OR($F3="Partial",$F3="No"),IF(Facility_Profile!$B$7="","",Facility_Profile!$B$7+$M3),"") | O3: =IF($F3="","Missing response",IF(OR($F3="Yes",$F3="Partial",$F3="No",$F3="N/A"),"OK","Check response")) -> Missing response | P3: =IF(OR($F3="Partial",$F3="No"),COUNTIF($F$3:$F3,"Partial")+COUNTIF($F$3:$F3,"No"),"") | Q3: =IFERROR($J3/$K3,"")
A4: 1 | B4: Governance, service model and accountability | C4: 1.2 | D4: P1 | E4: The SOP defines which AHD/OI services are provided on site, which are referred, and the responsible receiving hub for each service. | J4: =IF($F4="Yes",1,IF(OR($F4="Partial",$F4="No"),0,"")) | K4: =IF(OR($F4="Yes",$F4="Partial",$F4="No"),1,0) -> 0 | L4: =IF(AND($D4="P1",OR($F4="Partial",$F4="No")),"P1 gap",IF(OR($F4="Partial",$F4="No"),"Gap","")) | M4: =IF($D4="P1",30,IF($D4="P2",90,IF($D4="P3",180,""))) -> 30 | N4: =IF(OR($F4="Partial",$F4="No"),IF(Facility_Profile!$B$7="","",Facility_Profile!$B$7+$M4),"") | O4: =IF($F4="","Missing response",IF(OR($F4="Yes",$F4="Partial",$F4="No",$F4="N/A"),"OK","Check response")) -> Missing response | P4: =IF(OR($F4="Partial",$F4="No"),COUNTIF($F$3:$F4,"Partial")+COUNTIF($F$3:$F4,"No"),"") | Q4: =IFERROR($J4/$K4,"")
A5: 1 | B5: Governance, service model and accountability | C5: 1.3 | D5: P1 | E5: A same-day AHD pathway exists from HIV diagnosis or re-entry to clinical review, CD4/WHO staging, OI screening, prophylaxis/treatment decisions and follow-up booking. | J5: =IF($F5="Yes",1,IF(OR($F5="Partial",$F5="No"),0,"")) | K5: =IF(OR($F5="Yes",$F5="Partial",$F5="No"),1,0) -> 0 | L5: =IF(AND($D5="P1",OR($F5="Partial",$F5="No")),"P1 gap",IF(OR($F5="Partial",$F5="No"),"Gap","")) | M5: =IF($D5="P1",30,IF($D5="P2",90,IF($D5="P3",180,""))) -> 30 | N5: =IF(OR($F5="Partial",$F5="No"),IF(Facility_Profile!$B$7="","",Facility_Profile!$B$7+$M5),"") | O5: =IF($F5="","Missing response",IF(OR($F5="Yes",$F5="Partial",$F5="No",$F5="N/A"),"OK","Check response")) -> Missing response | P5: =IF(OR($F5="Partial",$F5="No"),COUNTIF($F$3:$F5,"Partial")+COUNTIF($F$3:$F5,"No"),"") | Q5: =IFERROR($J5/$K5,"")
A6: 1 | B6: Governance, service model and accountability | C6: 1.4 | D6: P2 | E6: Facility leadership reviews AHD/OI readiness at least quarterly and assigns owners for unresolved gaps. | J6: =IF($F6="Yes",1,IF(OR($F6="Partial",$F6="No"),0,"")) | K6: =IF(OR($F6="Yes",$F6="Partial",$F6="No"),1,0) -> 0 | L6: =IF(AND($D6="P1",OR($F6="Partial",$F6="No")),"P1 gap",IF(OR($F6="Partial",$F6="No"),"Gap","")) | M6: =IF($D6="P1",30,IF($D6="P2",90,IF($D6="P3",180,""))) -> 90 | N6: =IF(OR($F6="Partial",$F6="No"),IF(Facility_Profile!$B$7="","",Facility_Profile!$B$7+$M6),"") | O6: =IF($F6="","Missing response",IF(OR($F6="Yes",$F6="Partial",$F6="No",$F6="N/A"),"OK","Check response")) -> Missing response | P6: =IF(OR($F6="Partial",$F6="No"),COUNTIF($F$3:$F6,"Partial")+COUNTIF($F$3:$F6,"No"),"") | Q6: =IFERROR($J6/$K6,"")
A7: 1 | B7: Governance, service model and accountability | C7: 1.5 | D7: P2 | E7: The facility has visible client-flow/job aids for AHD entry points: HIV testing, ART, TB, PMTCT/MCH, inpatient/emergency/OPD, pediatrics and community return-to-care. | J7: =IF($F7="Yes",1,IF(OR($F7="Partial",$F7="No"),0,"")) | K7: =IF(OR($F7="Yes",$F7="Partial",$F7="No"),1,0) -> 0 | L7: =IF(AND($D7="P1",OR($F7="Partial",$F7="No")),"P1 gap",IF(OR($F7="Partial",$F7="No"),"Gap","")) | M7: =IF($D7="P1",30,IF($D7="P2",90,IF($D7="P3",180,""))) -> 90 | N7: =IF(OR($F7="Partial",$F7="No"),IF(Facility_Profile!$B$7="","",Facility_Profile!$B$7+$M7),"") | O7: =IF($F7="","Missing response",IF(OR($F7="Yes",$F7="Partial",$F7="No",$F7="N/A"),"OK","Check response")) -> Missing response | P7: =IF(OR($F7="Partial",$F7="No"),COUNTIF($F$3:$F7,"Partial")+COUNTIF($F$3:$F7,"No"),"") | Q7: =IFERROR($J7/$K7,"")
A8: 1 | B8: Governance, service model and accountability | C8: 1.6 | D8: P2 | E8: Confidentiality, consent, stigma-reduction and respectful-care expectations are included in AHD/OI workflows. | J8: =IF($F8="Yes",1,IF(OR($F8="Partial",$F8="No"),0,"")) | K8: =IF(OR($F8="Yes",$F8="Partial",$F8="No"),1,0) -> 0 | L8: =IF(AND($D8="P1",OR($F8="Partial",$F8="No")),"P1 gap",IF(OR($F8="Partial",$F8="No"),"Gap","")) | M8: =IF($D8="P1",30,IF($D8="P2",90,IF($D8="P3",180,""))) -> 90 | N8: =IF(OR($F8="Partial",$F8="No"),IF(Facility_Profile!$B$7="","",Facility_Profile!$B$7+$M8),"") | O8: =IF($F8="","Missing response",IF(OR($F8="Yes",$F8="Partial",$F8="No",$F8="N/A"),"OK","Check response")) -> Missing response | P8: =IF(OR($F8="Partial",$F8="No"),COUNTIF($F$3:$F8,"Partial")+COUNTIF($F$3:$F8,"No"),"") | Q8: =IFERROR($J8/$K8,"")
A9: 2 | B9: Screening, early detection and identification of clients with AHD | C9: 2.1 | D9: P1 | E9: Staff use the WHO AHD definition: CD4 <=200 cells/mm3 for adults, adolescents and children >=5 years. | J9: =IF($F9="Yes",1,IF(OR($F9="Partial",$F9="No"),0,"")) | K9: =IF(OR($F9="Yes",$F9="Partial",$F9="No"),1,0) -> 0 | L9: =IF(AND($D9="P1",OR($F9="Partial",$F9="No")),"P1 gap",IF(OR($F9="Partial",$F9="No"),"Gap","")) | M9: =IF($D9="P1",30,IF($D9="P2",90,IF($D9="P3",180,""))) -> 30 | N9: =IF(OR($F9="Partial",$F9="No"),IF(Facility_Profile!$B$7="","",Facility_Profile!$B$7+$M9),"") | O9: =IF($F9="","Missing response",IF(OR($F9="Yes",$F9="Partial",$F9="No",$F9="N/A"),"OK","Check response")) -> Missing response | P9: =IF(OR($F9="Partial",$F9="No"),COUNTIF($F$3:$F9,"Partial")+COUNTIF($F$3:$F9,"No"),"") | Q9: =IFERROR($J9/$K9,"")
A10: 2 | B10: Screening, early detection and identification of clients with AHD | C10: 2.2 | D10: P1 | E10: Children <5 years living with HIV are treated as having AHD unless on ART for >1 year and clinically stable. | J10: =IF($F10="Yes",1,IF(OR($F10="Partial",$F10="No"),0,"")) | K10: =IF(OR($F10="Yes",$F10="Partial",$F10="No"),1,0) -> 0 | L10: =IF(AND($D10="P1",OR($F10="Partial",$F10="No")),"P1 gap",IF(OR($F10="Partial",$F10="No"),"Gap","")) | M10: =IF($D10="P1",30,IF($D10="P2",90,IF($D10="P3",180,""))) -> 30 | N10: =IF(OR($F10="Partial",$F10="No"),IF(Facility_Profile!$B$7="","",Facility_Profile!$B$7+$M10),"") | O10: =IF($F10="","Missing response",IF(OR($F10="Yes",$F10="Partial",$F10="No",$F10="N/A"),"OK","Check response")) -> Missing response | P10: =IF(OR($F10="Partial",$F10="No"),COUNTIF($F$3:$F10,"Partial")+COUNTIF($F$3:$F10,"No"),"") | Q10: =IFERROR($J10/$K10,"")
A11: 2 | B11: Screening, early detection and identification of clients with AHD | C11: 2.3 | D11: P1 | E11: Where CD4 is not available, WHO clinical stage 3 or 4 at presentation is used to identify AHD. | J11: =IF($F11="Yes",1,IF(OR($F11="Partial",$F11="No"),0,"")) | K11: =IF(OR($F11="Yes",$F11="Partial",$F11="No"),1,0) -> 0 | L11: =IF(AND($D11="P1",OR($F11="Partial",$F11="No")),"P1 gap",IF(OR($F11="Partial",$F11="No"),"Gap","")) | M11: =IF($D11="P1",30,IF($D11="P2",90,IF($D11="P3",180,""))) -> 30 | N11: =IF(OR($F11="Partial",$F11="No"),IF(Facility_Profile!$B$7="","",Facility_Profile!$B$7+$M11),"") | O11: =IF($F11="","Missing response",IF(OR($F11="Yes",$F11="Partial",$F11="No",$F11="N/A"),"OK","Check response")) -> Missing response | P11: =IF(OR($F11="Partial",$F11="No"),COUNTIF($F$3:$F11,"Partial")+COUNTIF($F$3:$F11,"No"),"") | Q11: =IFERROR($J11/$K11,"")
A12: 2 | B12: Screening, early detection and identification of clients with AHD | C12: 2.4 | D12: P1 | E12: CD4 testing or clinical staging is triggered for all newly diagnosed clients, clients returning after interruption, clients with suspected/confirmed treatment failure and seriously ill PLHIV. | J12: =IF($F12="Yes",1,IF(OR($F12="Partial",$F12="No"),0,"")) | K12: =IF(OR($F12="Yes",$F12="Partial",$F12="No"),1,0) -> 0 | L12: =IF(AND($D12="P1",OR($F12="Partial",$F12="No")),"P1 gap",IF(OR($F12="Partial",$F12="No"),"Gap","")) | M12: =IF($D12="P1",30,IF($D12="P2",90,IF($D12="P3",180,""))) -> 30 | N12: =IF(OR($F12="Partial",$F12="No"),IF(Facility_Profile!$B$7="","",Facility_Profile!$B$7+$M12),"") | O12: =IF($F12="","Missing response",IF(OR($F12="Yes",$F12="Partial",$F12="No",$F12="N/A"),"OK","Check response")) -> Missing response | P12: =IF(OR($F12="Partial",$F12="No"),COUNTIF($F$3:$F12,"Partial")+COUNTIF($F$3:$F12,"No"),"") | Q12: =IFERROR($J12/$K12,"")
A13: 2 | B13: Screening, early detection and identification of clients with AHD | C13: 2.5 | D13: P1 | E13: ART interruption, missed visits, high viral load, prior OI, weight loss or severe symptoms are flagged as high-risk re-entry triggers. | J13: =IF($F13="Yes",1,IF(OR($F13="Partial",$F13="No"),0,"")) | K13: =IF(OR($F13="Yes",$F13="Partial",$F13="No"),1,0) -> 0 | L13: =IF(AND($D13="P1",OR($F13="Partial",$F13="No")),"P1 gap",IF(OR($F13="Partial",$F13="No"),"Gap","")) | M13: =IF($D13="P1",30,IF($D13="P2",90,IF($D13="P3",180,""))) -> 30 | N13: =IF(OR($F13="Partial",$F13="No"),IF(Facility_Profile!$B$7="","",Facility_Profile!$B$7+$M13),"") | O13: =IF($F13="","Missing response",IF(OR($F13="Yes",$F13="Partial",$F13="No",$F13="N/A"),"OK","Check response")) -> Missing response | P13: =IF(OR($F13="Partial",$F13="No"),COUNTIF($F$3:$F13,"Partial")+COUNTIF($F$3:$F13,"No"),"") | Q13: =IFERROR($J13/$K13,"")
A14: 2 | B14: Screening, early detection and identification of clients with AHD | C14: 2.6 | D14: P2 | E14: AHD status is documented clearly in the clinical record/register/DAMA and visible to clinicians, pharmacy and follow-up teams. | J14: =IF($F14="Yes",1,IF(OR($F14="Partial",$F14="No"),0,"")) | K14: =IF(OR($F14="Yes",$F14="Partial",$F14="No"),1,0) -> 0 | L14: =IF(AND($D14="P1",OR($F14="Partial",$F14="No")),"P1 gap",IF(OR($F14="Partial",$F14="No"),"Gap","")) | M14: =IF($D14="P1",30,IF($D14="P2",90,IF($D14="P3",180,""))) -> 90 | N14: =IF(OR($F14="Partial",$F14="No"),IF(Facility_Profile!$B$7="","",Facility_Profile!$B$7+$M14),"") | O14: =IF($F14="","Missing response",IF(OR($F14="Yes",$F14="Partial",$F14="No",$F14="N/A"),"OK","Check response")) -> Missing response | P14: =IF(OR($F14="Partial",$F14="No"),COUNTIF($F$3:$F14,"Partial")+COUNTIF($F$3:$F14,"No"),"") | Q14: =IFERROR($J14/$K14,"")
... A47: 6 | B47: Cryptococcal disease screening, diagnosis, treatment and follow-up | C47: 6.9 | D47: P2 | E47: CrAg testing, positive results, treatment initiation, referral completion and outcomes are monitored monthly. | J47: =IF($F47="Yes",1,IF(OR($F47="Partial",$F47="No"),0,"")) | K47: =IF(OR($F47="Yes",$F47="Partial",$F47="No"),1,0) -> 0 | L47: =IF(AND($D47="P1",OR($F47="Partial",$F47="No")),"P1 gap",IF(OR($F47="Partial",$F47="No"),"Gap","")) | M47: =IF($D47="P1",30,IF($D47="P2",90,IF($D47="P3",180,""))) -> 90 | N47: =IF(OR($F47="Partial",$F47="No"),IF(Facility_Profile!$B$7="","",Facility_Profile!$B$7+$M47),"") | O47: =IF($F47="","Missing response",IF(OR($F47="Yes",$F47="Partial",$F47="No",$F47="N/A"),"OK","Check response")) -> Missing response | P47: =IF(OR($F47="Partial",$F47="No"),COUNTIF($F$3:$F47,"Partial")+COUNTIF($F$3:$F47,"No"),"") | Q47: =IFERROR($J47/$K47,"")
A48: 7 | B48: Toxoplasmosis and other opportunistic infections readiness | C48: 7.1 | D48: P1 | E48: Staff can recognize and promptly assess the clinical features and danger signs associated with: | F48: =IF(COUNTIF($F$49:$F$54,"Yes")+COUNTIF($F$49:$F$54,"Partial")+COUNTIF($F$49:$F$54,"No")+COUNTIF($F$49:$F$54,"N/A")<6,"Incomplete - complete 6 OI lines",IF($K48=0,"All six marked N/A",$J48&"/"&$K48&" ready")) -> Incomplete - complete 6 OI lines | G48: Complete the six condition-specific scoring lines immediately below. The parent total is calculated automatically and is not scored again. | J48: =SUM($J$49:$J$54) -> 1 | K48: =SUM($K$49:$K$54) -> 2 | L48: =IF(COUNTIF($F$49:$F$54,"Partial")+COUNTIF($F$49:$F$54,"No")>0,"See sub-item gap(s)","") -> See sub-item gap(s) | M48: =IF($D48="P1",30,IF($D48="P2",90,IF($D48="P3",180,""))) -> 30 | N48: =IF(COUNT($N$49:$N$54)=0,"",MIN($N$49:$N$54)) | O48: ="Parent summary - not scored separately" -> Parent summary - not scored separately | P48: ="" | Q48: =IFERROR($J48/$K48,"") -> 0.5
A49: 7 | B49: Toxoplasmosis and other opportunistic infections readiness | C49: 7.1.1 | D49: P1 | E49: Toxoplasmosis Clinical features: new or severe headache, fever, focal neurological deficit or weakness, seizures, confusion or reduced consciousness. Danger signs: convulsions, unconsciousness, rapidly worsening focal signs, inability to walk or drink, repeated vomiting, or signs of raised intracranial pressure requiring urgent stabilization/referral. | F49: Yes | J49: =IF($F49="Yes",1,IF(OR($F49="Partial",$F49="No"),0,"")) -> 1 | K49: =IF(OR($F49="Yes",$F49="Partial",$F49="No"),1,0) -> 1 | L49: =IF(AND($D49="P1",OR($F49="Partial",$F49="No")),"P1 gap",IF(OR($F49="Partial",$F49="No"),"Gap","")) | M49: =IF($D49="P1",30,IF($D49="P2",90,IF($D49="P3",180,""))) -> 30 | N49: =IF(OR($F49="Partial",$F49="No"),IF(Facility_Profile!$B$7="","",Facility_Profile!$B$7+$M49),"") | O49: =IF($F49="","Missing response",IF(OR($F49="Yes",$F49="Partial",$F49="No",$F49="N/A"),"OK","Check response")) -> OK | P49: =IF(OR($F49="Partial",$F49="No"),COUNTIF($F$3:$F49,"Partial")+COUNTIF($F$3:$F49,"No"),"") | Q49: =IFERROR($J49/$K49,"") -> 1
A50: 7 | B50: Toxoplasmosis and other opportunistic infections readiness | C50: 7.1.2 | D50: P1 | E50: Pneumocystis pneumonia Clinical features: subacute non-productive cough, progressive shortness of breath, rapid breathing, fever or low-grade fever, bilateral crepitations/reduced air entry, and hypoxaemia. Danger signs: severe respiratory distress, chest indrawing or cyanosis, persistently low oxygen saturation, exhaustion, altered consciousness, or inability to feed/drink. | F50: Partial | J50: =IF($F50="Yes",1,IF(OR($F50="Partial",$F50="No"),0,"")) -> 0 | K50: =IF(OR($F50="Yes",$F50="Partial",$F50="No"),1,0) -> 1 | L50: =IF(AND($D50="P1",OR($F50="Partial",$F50="No")),"P1 gap",IF(OR($F50="Partial",$F50="No"),"Gap","")) -> P1 gap | M50: =IF($D50="P1",30,IF($D50="P2",90,IF($D50="P3",180,""))) -> 30 | N50: =IF(OR($F50="Partial",$F50="No"),IF(Facility_Profile!$B$7="","",Facility_Profile!$B$7+$M50),"") | O50: =IF($F50="","Missing response",IF(OR($F50="Yes",$F50="Partial",$F50="No",$F50="N/A"),"OK","Check response")) -> OK | P50: =IF(OR($F50="Partial",$F50="No"),COUNTIF($F$3:$F50,"Partial")+COUNTIF($F$3:$F50,"No"),"") -> 1 | Q50: =IFERROR($J50/$K50,"") -> 0
A51: 7 | B51: Toxoplasmosis and other opportunistic infections readiness | C51: 7.1.3 | D51: P1 | E51: Histoplasmosis Clinical features: persistent fever, marked weight loss, fatigue, cough or dyspnoea, lymphadenopathy, hepatosplenomegaly, mucocutaneous lesions, gastrointestinal symptoms, and pallor/bleeding suggesting cytopenias. Danger signs: shock, severe respiratory distress, altered consciousness/CNS features, severe anaemia/bleeding, or rapid deterioration. | J51: =IF($F51="Yes",1,IF(OR($F51="Partial",$F51="No"),0,"")) | K51: =IF(OR($F51="Yes",$F51="Partial",$F51="No"),1,0) -> 0 | L51: =IF(AND($D51="P1",OR($F51="Partial",$F51="No")),"P1 gap",IF(OR($F51="Partial",$F51="No"),"Gap","")) | M51: =IF($D51="P1",30,IF($D51="P2",90,IF($D51="P3",180,""))) -> 30 | N51: =IF(OR($F51="Partial",$F51="No"),IF(Facility_Profile!$B$7="","",Facility_Profile!$B$7+$M51),"") | O51: =IF($F51="","Missing response",IF(OR($F51="Yes",$F51="Partial",$F51="No",$F51="N/A"),"OK","Check response")) -> Missing response | P51: =IF(OR($F51="Partial",$F51="No"),COUNTIF($F$3:$F51,"Partial")+COUNTIF($F$3:$F51,"No"),"") | Q51: =IFERROR($J51/$K51,"")
A52: 7 | B52: Toxoplasmosis and other opportunistic infections readiness | C52: 7.1.4 | D52: P1 | E52: Chronic diarrhea Clinical features: diarrhoea lasting 14 days or longer, frequent watery or bloody stools, abdominal pain, fever, weight loss, poor intake, and reduced urine output. Danger signs: severe dehydration or shock, lethargy, inability to drink, repeated vomiting, blood in stool, severe malnutrition, sepsis, or worsening renal function. | J52: =IF($F52="Yes",1,IF(OR($F52="Partial",$F52="No"),0,"")) | K52: =IF(OR($F52="Yes",$F52="Partial",$F52="No"),1,0) -> 0 | L52: =IF(AND($D52="P1",OR($F52="Partial",$F52="No")),"P1 gap",IF(OR($F52="Partial",$F52="No"),"Gap","")) | M52: =IF($D52="P1",30,IF($D52="P2",90,IF($D52="P3",180,""))) -> 30 | N52: =IF(OR($F52="Partial",$F52="No"),IF(Facility_Profile!$B$7="","",Facility_Profile!$B$7+$M52),"") | O52: =IF($F52="","Missing response",IF(OR($F52="Yes",$F52="Partial",$F52="No",$F52="N/A"),"OK","Check response")) -> Missing response | P52: =IF(OR($F52="Partial",$F52="No"),COUNTIF($F$3:$F52,"Partial")+COUNTIF($F$3:$F52,"No"),"") | Q52: =IFERROR($J52/$K52,"")
A53: 7 | B53: Toxoplasmosis and other opportunistic infections readiness | C53: 7.1.5 | D53: P1 | E53: Oral/esophageal candidiasis Clinical features: oral erythema with removable white-beige plaques, angular cheilitis, painful or difficult swallowing, retrosternal pain, refusal/reluctance to eat, excessive salivation, or crying with feeds. Danger signs: inability to swallow fluids/medicines, dehydration, severe pain, airway concern, or suspected disseminated/refractory disease. | J53: =IF($F53="Yes",1,IF(OR($F53="Partial",$F53="No"),0,"")) | K53: =IF(OR($F53="Yes",$F53="Partial",$F53="No"),1,0) -> 0 | L53: =IF(AND($D53="P1",OR($F53="Partial",$F53="No")),"P1 gap",IF(OR($F53="Partial",$F53="No"),"Gap","")) | M53: =IF($D53="P1",30,IF($D53="P2",90,IF($D53="P3",180,""))) -> 30 | N53: =IF(OR($F53="Partial",$F53="No"),IF(Facility_Profile!$B$7="","",Facility_Profile!$B$7+$M53),"") | O53: =IF($F53="","Missing response",IF(OR($F53="Yes",$F53="Partial",$F53="No",$F53="N/A"),"OK","Check response")) -> Missing response | P53: =IF(OR($F53="Partial",$F53="No"),COUNTIF($F$3:$F53,"Partial")+COUNTIF($F$3:$F53,"No"),"") | Q53: =IFERROR($J53/$K53,"")
A54: 7 | B54: Toxoplasmosis and other opportunistic infections readiness | C54: 7.1.6 | D54: P1 | E54: Malnutrition Clinical features: visible wasting or unintentional weight loss, low BMI/weight-for-height, low MUAC, bilateral pitting oedema, poor appetite, and faltering growth. Danger signs/complications: lethargy, hypoglycaemia, hypothermia, shock/dehydration, severe infection, inability to eat/drink, or oedema with medical complications. | J54: =IF($F54="Yes",1,IF(OR($F54="Partial",$F54="No"),0,"")) | K54: =IF(OR($F54="Yes",$F54="Partial",$F54="No"),1,0) -> 0 | L54: =IF(AND($D54="P1",OR($F54="Partial",$F54="No")),"P1 gap",IF(OR($F54="Partial",$F54="No"),"Gap","")) | M54: =IF($D54="P1",30,IF($D54="P2",90,IF($D54="P3",180,""))) -> 30 | N54: =IF(OR($F54="Partial",$F54="No"),IF(Facility_Profile!$B$7="","",Facility_Profile!$B$7+$M54),"") | O54: =IF($F54="","Missing response",IF(OR($F54="Yes",$F54="Partial",$F54="No",$F54="N/A"),"OK","Check response")) -> Missing response | P54: =IF(OR($F54="Partial",$F54="No"),COUNTIF($F$3:$F54,"Partial")+COUNTIF($F$3:$F54,"No"),"") | Q54: =IFERROR($J54/$K54,"")
A55: 7 | B55: Toxoplasmosis and other opportunistic infections readiness | C55: 7.2 | D55: P1 | E55: Appropriate diagnostic tests, clinical assessment tools, specimen referral and result-return pathways are available for: | F55: =IF(COUNTIF($F$56:$F$61,"Yes")+COUNTIF($F$56:$F$61,"Partial")+COUNTIF($F$56:$F$61,"No")+COUNTIF($F$56:$F$61,"N/A")<6,"Incomplete - complete 6 OI lines",IF($K55=0,"All six marked N/A",$J55&"/"&$K55&" ready")) -> Incomplete - complete 6 OI lines | G55: Complete the six condition-specific scoring lines immediately below. The parent total is calculated automatically and is not scored again. | J55: =SUM($J$56:$J$61) -> 0 | K55: =SUM($K$56:$K$61) -> 0 | L55: =IF(COUNTIF($F$56:$F$61,"Partial")+COUNTIF($F$56:$F$61,"No")>0,"See sub-item gap(s)","") | M55: =IF($D55="P1",30,IF($D55="P2",90,IF($D55="P3",180,""))) -> 30 | N55: =IF(COUNT($N$56:$N$61)=0,"",MIN($N$56:$N$61)) | O55: ="Parent summary - not scored separately" -> Parent summary - not scored separately | P55: ="" | Q55: =IFERROR($J55/$K55,"")
A56: 7 | B56: Toxoplasmosis and other opportunistic infections readiness | C56: 7.2.1 | D56: P1 | E56: Toxoplasmosis brain CT/MRI referral where available; Toxoplasma IgG ; CSF testing/PCR | J56: =IF($F56="Yes",1,IF(OR($F56="Partial",$F56="No"),0,"")) | K56: =IF(OR($F56="Yes",$F56="Partial",$F56="No"),1,0) -> 0 | L56: =IF(AND($D56="P1",OR($F56="Partial",$F56="No")),"P1 gap",IF(OR($F56="Partial",$F56="No"),"Gap","")) | M56: =IF($D56="P1",30,IF($D56="P2",90,IF($D56="P3",180,""))) -> 30 | N56: =IF(OR($F56="Partial",$F56="No"),IF(Facility_Profile!$B$7="","",Facility_Profile!$B$7+$M56),"") | O56: =IF($F56="","Missing response",IF(OR($F56="Yes",$F56="Partial",$F56="No",$F56="N/A"),"OK","Check response")) -> Missing response | P56: =IF(OR($F56="Partial",$F56="No"),COUNTIF($F$3:$F56,"Partial")+COUNTIF($F$3:$F56,"No"),"") | Q56: =IFERROR($J56/$K56,"")
A57: 7 | B57: Toxoplasmosis and other opportunistic infections readiness | C57: 7.2.2 | D57: P1 | E57: Pneumocystis pneumonia pulse oximetry; chest X-ray; induced sputum or nasopharyngeal aspirate, and bronchoalveolar lavage at referral level, for microscopy/PCR where available. | J57: =IF($F57="Yes",1,IF(OR($F57="Partial",$F57="No"),0,"")) | K57: =IF(OR($F57="Yes",$F57="Partial",$F57="No"),1,0) -> 0 | L57: =IF(AND($D57="P1",OR($F57="Partial",$F57="No")),"P1 gap",IF(OR($F57="Partial",$F57="No"),"Gap","")) | M57: =IF($D57="P1",30,IF($D57="P2",90,IF($D57="P3",180,""))) -> 30 | N57: =IF(OR($F57="Partial",$F57="No"),IF(Facility_Profile!$B$7="","",Facility_Profile!$B$7+$M57),"") | O57: =IF($F57="","Missing response",IF(OR($F57="Yes",$F57="Partial",$F57="No",$F57="N/A"),"OK","Check response")) -> Missing response | P57: =IF(OR($F57="Partial",$F57="No"),COUNTIF($F$3:$F57,"Partial")+COUNTIF($F$3:$F57,"No"),"") | Q57: =IFERROR($J57/$K57,"")
A58: 7 | B58: Toxoplasmosis and other opportunistic infections readiness | C58: 7.2.3 | D58: P1 | E58: Histoplasmosis circulating Histoplasma antigen assay using urine and/or serum where available; fungal microscopy/histopathology and culture through a referral laboratory; full blood count and renal/liver assessment for severity and treatment monitoring. | J58: =IF($F58="Yes",1,IF(OR($F58="Partial",$F58="No"),0,"")) | K58: =IF(OR($F58="Yes",$F58="Partial",$F58="No"),1,0) -> 0 | L58: =IF(AND($D58="P1",OR($F58="Partial",$F58="No")),"P1 gap",IF(OR($F58="Partial",$F58="No"),"Gap","")) | M58: =IF($D58="P1",30,IF($D58="P2",90,IF($D58="P3",180,""))) -> 30 | N58: =IF(OR($F58="Partial",$F58="No"),IF(Facility_Profile!$B$7="","",Facility_Profile!$B$7+$M58),"") | O58: =IF($F58="","Missing response",IF(OR($F58="Yes",$F58="Partial",$F58="No",$F58="N/A"),"OK","Check response")) -> Missing response | P58: =IF(OR($F58="Partial",$F58="No"),COUNTIF($F$3:$F58,"Partial")+COUNTIF($F$3:$F58,"No"),"") | Q58: =IFERROR($J58/$K58,"")
A59: 7 | B59: Toxoplasmosis and other opportunistic infections readiness | C59: 7.2.4 | D59: P1 | E59: Chronic diarrhea stool examination for ova/parasites and modified acid-fast testing for coccidian parasites where available; stool culture/other pathogen tests based on syndrome and exposure; electrolytes/renal function for severe illness. | J59: =IF($F59="Yes",1,IF(OR($F59="Partial",$F59="No"),0,"")) | K59: =IF(OR($F59="Yes",$F59="Partial",$F59="No"),1,0) -> 0 | L59: =IF(AND($D59="P1",OR($F59="Partial",$F59="No")),"P1 gap",IF(OR($F59="Partial",$F59="No"),"Gap","")) | M59: =IF($D59="P1",30,IF($D59="P2",90,IF($D59="P3",180,""))) -> 30 | N59: =IF(OR($F59="Partial",$F59="No"),IF(Facility_Profile!$B$7="","",Facility_Profile!$B$7+$M59),"") | O59: =IF($F59="","Missing response",IF(OR($F59="Yes",$F59="Partial",$F59="No",$F59="N/A"),"OK","Check response")) -> Missing response | P59: =IF(OR($F59="Partial",$F59="No"),COUNTIF($F$3:$F59,"Partial")+COUNTIF($F$3:$F59,"No"),"") | Q59: =IFERROR($J59/$K59,"")
A60: 7 | B60: Toxoplasmosis and other opportunistic infections readiness | C60: 7.2.5 | D60: P1 | E60: Oral/esophageal candidiasis hydration and nutrition; clinical diagnosis or treatment trial for typical disease; KOH/Gram stain/culture for atypical, recurrent or refractory cases where available. | J60: =IF($F60="Yes",1,IF(OR($F60="Partial",$F60="No"),0,"")) | K60: =IF(OR($F60="Yes",$F60="Partial",$F60="No"),1,0) -> 0 | L60: =IF(AND($D60="P1",OR($F60="Partial",$F60="No")),"P1 gap",IF(OR($F60="Partial",$F60="No"),"Gap","")) | M60: =IF($D60="P1",30,IF($D60="P2",90,IF($D60="P3",180,""))) -> 30 | N60: =IF(OR($F60="Partial",$F60="No"),IF(Facility_Profile!$B$7="","",Facility_Profile!$B$7+$M60),"") | O60: =IF($F60="","Missing response",IF(OR($F60="Yes",$F60="Partial",$F60="No",$F60="N/A"),"OK","Check response")) -> Missing response | P60: =IF(OR($F60="Partial",$F60="No"),COUNTIF($F$3:$F60,"Partial")+COUNTIF($F$3:$F60,"No"),"") | Q60: =IFERROR($J60/$K60,"")
A61: 7 | B61: Toxoplasmosis and other opportunistic infections readiness | C61: 7.2.6 | D61: P1 | E61: Malnutrition calibrated weight scale, length/height board, BMI/weight-for-height and age-appropriate growth charts, MUAC tape, | J61: =IF($F61="Yes",1,IF(OR($F61="Partial",$F61="No"),0,"")) | K61: =IF(OR($F61="Yes",$F61="Partial",$F61="No"),1,0) -> 0 | L61: =IF(AND($D61="P1",OR($F61="Partial",$F61="No")),"P1 gap",IF(OR($F61="Partial",$F61="No"),"Gap","")) | M61: =IF($D61="P1",30,IF($D61="P2",90,IF($D61="P3",180,""))) -> 30 | N61: =IF(OR($F61="Partial",$F61="No"),IF(Facility_Profile!$B$7="","",Facility_Profile!$B$7+$M61),"") | O61: =IF($F61="","Missing response",IF(OR($F61="Yes",$F61="Partial",$F61="No",$F61="N/A"),"OK","Check response")) -> Missing response | P61: =IF(OR($F61="Partial",$F61="No"),COUNTIF($F$3:$F61,"Partial")+COUNTIF($F$3:$F61,"No"),"") | Q61: =IFERROR($J61/$K61,"")
A62: 7 | B62: Toxoplasmosis and other opportunistic infections readiness | C62: 7.3 | D62: P1 | E62: Current treatment, prophylaxis where applicable, stabilization and referral protocols are available and used for: | F62: =IF(COUNTIF($F$63:$F$68,"Yes")+COUNTIF($F$63:$F$68,"Partial")+COUNTIF($F$63:$F$68,"No")+COUNTIF($F$63:$F$68,"N/A")<6,"Incomplete - complete 6 OI lines",IF($K62=0,"All six marked N/A",$J62&"/"&$K62&" ready")) -> Incomplete - complete 6 OI lines | G62: Complete the six condition-specific scoring lines immediately below. The parent total is calculated automatically and is not scored again. | J62: =SUM($J$63:$J$68) -> 0 | K62: =SUM($K$63:$K$68) -> 0 | L62: =IF(COUNTIF($F$63:$F$68,"Partial")+COUNTIF($F$63:$F$68,"No")>0,"See sub-item gap(s)","") | M62: =IF($D62="P1",30,IF($D62="P2",90,IF($D62="P3",180,""))) -> 30 | N62: =IF(COUNT($N$63:$N$68)=0,"",MIN($N$63:$N$68)) | O62: ="Parent summary - not scored separately" -> Parent summary - not scored separately | P62: ="" | Q62: =IFERROR($J62/$K62,"")
A63: 7 | B63: Toxoplasmosis and other opportunistic infections readiness | C63: 7.3.1 | D63: P1 | E63: Toxoplasmosis co-trimoxazole or pyrimethamine-based regimen according to national guidance); co-trimoxazole prophylaxis for eligible people | J63: =IF($F63="Yes",1,IF(OR($F63="Partial",$F63="No"),0,"")) | K63: =IF(OR($F63="Yes",$F63="Partial",$F63="No"),1,0) -> 0 | L63: =IF(AND($D63="P1",OR($F63="Partial",$F63="No")),"P1 gap",IF(OR($F63="Partial",$F63="No"),"Gap","")) | M63: =IF($D63="P1",30,IF($D63="P2",90,IF($D63="P3",180,""))) -> 30 | N63: =IF(OR($F63="Partial",$F63="No"),IF(Facility_Profile!$B$7="","",Facility_Profile!$B$7+$M63),"") | O63: =IF($F63="","Missing response",IF(OR($F63="Yes",$F63="Partial",$F63="No",$F63="N/A"),"OK","Check response")) -> Missing response | P63: =IF(OR($F63="Partial",$F63="No"),COUNTIF($F$3:$F63,"Partial")+COUNTIF($F$3:$F63,"No"),"") | Q63: =IFERROR($J63/$K63,"")
A64: 7 | B64: Toxoplasmosis and other opportunistic infections readiness | C64: 7.3.2 | D64: P1 | E64: Pneumocystis pneumonia high-dose co-trimoxazole treatment , oxygen and supportive care; adjunctive corticosteroid protocol for severe hypoxaemia/respiratory distress; admission/referral for severe disease or treatment failure; co-trimoxazole prophylaxis and timely ART according to national guidance. | J64: =IF($F64="Yes",1,IF(OR($F64="Partial",$F64="No"),0,"")) | K64: =IF(OR($F64="Yes",$F64="Partial",$F64="No"),1,0) -> 0 | L64: =IF(AND($D64="P1",OR($F64="Partial",$F64="No")),"P1 gap",IF(OR($F64="Partial",$F64="No"),"Gap","")) | M64: =IF($D64="P1",30,IF($D64="P2",90,IF($D64="P3",180,""))) -> 30 | N64: =IF(OR($F64="Partial",$F64="No"),IF(Facility_Profile!$B$7="","",Facility_Profile!$B$7+$M64),"") | O64: =IF($F64="","Missing response",IF(OR($F64="Yes",$F64="Partial",$F64="No",$F64="N/A"),"OK","Check response")) -> Missing response | P64: =IF(OR($F64="Partial",$F64="No"),COUNTIF($F$3:$F64,"Partial")+COUNTIF($F$3:$F64,"No"),"") | Q64: =IFERROR($J64/$K64,"")
A65: 7 | B65: Toxoplasmosis and other opportunistic infections readiness | C65: 7.3.3 | D65: P1 | E65: Histoplasmosis liposomal amphotericin B induction for severe/moderately severe disseminated disease followed by itraconazole; itraconazole for mild/moderate disease where appropriate; toxicity and interaction monitoring; rapid referral for severe/CNS disease; and ART initiation as soon as clinically appropriate when there is no CNS involvement. | J65: =IF($F65="Yes",1,IF(OR($F65="Partial",$F65="No"),0,"")) | K65: =IF(OR($F65="Yes",$F65="Partial",$F65="No"),1,0) -> 0 | L65: =IF(AND($D65="P1",OR($F65="Partial",$F65="No")),"P1 gap",IF(OR($F65="Partial",$F65="No"),"Gap","")) | M65: =IF($D65="P1",30,IF($D65="P2",90,IF($D65="P3",180,""))) -> 30 | N65: =IF(OR($F65="Partial",$F65="No"),IF(Facility_Profile!$B$7="","",Facility_Profile!$B$7+$M65),"") | O65: =IF($F65="","Missing response",IF(OR($F65="Yes",$F65="Partial",$F65="No",$F65="N/A"),"OK","Check response")) -> Missing response | P65: =IF(OR($F65="Partial",$F65="No"),COUNTIF($F$3:$F65,"Partial")+COUNTIF($F$3:$F65,"No"),"") | Q65: =IFERROR($J65/$K65,"")
A66: 7 | B66: Toxoplasmosis and other opportunistic infections readiness | C66: 7.3.4 | D66: P1 | E66: Chronic diarrhea low-osmolarity ORS and continued feeding; IV fluids for severe dehydration/shock; zinc for children and nutrition/micronutrient support for persistent diarrhoea; | J66: =IF($F66="Yes",1,IF(OR($F66="Partial",$F66="No"),0,"")) | K66: =IF(OR($F66="Yes",$F66="Partial",$F66="No"),1,0) -> 0 | L66: =IF(AND($D66="P1",OR($F66="Partial",$F66="No")),"P1 gap",IF(OR($F66="Partial",$F66="No"),"Gap","")) | M66: =IF($D66="P1",30,IF($D66="P2",90,IF($D66="P3",180,""))) -> 30 | N66: =IF(OR($F66="Partial",$F66="No"),IF(Facility_Profile!$B$7="","",Facility_Profile!$B$7+$M66),"") | O66: =IF($F66="","Missing response",IF(OR($F66="Yes",$F66="Partial",$F66="No",$F66="N/A"),"OK","Check response")) -> Missing response | P66: =IF(OR($F66="Partial",$F66="No"),COUNTIF($F$3:$F66,"Partial")+COUNTIF($F$3:$F66,"No"),"") | Q66: =IFERROR($J66/$K66,"")
A67: 7 | B67: Toxoplasmosis and other opportunistic infections readiness | C67: 7.3.5 | D67: P1 | E67: Oral/esophageal candidiasis topical nystatin or miconazole for uncomplicated oral disease where appropriate; systemic fluconazole for oesophageal or extensive disease; hydration, analgesia and nutrition support; referral and alternative therapy for inability to swallow, severe disease, treatment failure, recurrent disease or suspected azole resistance. | J67: =IF($F67="Yes",1,IF(OR($F67="Partial",$F67="No"),0,"")) | K67: =IF(OR($F67="Yes",$F67="Partial",$F67="No"),1,0) -> 0 | L67: =IF(AND($D67="P1",OR($F67="Partial",$F67="No")),"P1 gap",IF(OR($F67="Partial",$F67="No"),"Gap","")) | M67: =IF($D67="P1",30,IF($D67="P2",90,IF($D67="P3",180,""))) -> 30 | N67: =IF(OR($F67="Partial",$F67="No"),IF(Facility_Profile!$B$7="","",Facility_Profile!$B$7+$M67),"") | O67: =IF($F67="","Missing response",IF(OR($F67="Yes",$F67="Partial",$F67="No",$F67="N/A"),"OK","Check response")) -> Missing response | P67: =IF(OR($F67="Partial",$F67="No"),COUNTIF($F$3:$F67,"Partial")+COUNTIF($F$3:$F67,"No"),"") | Q67: =IFERROR($J67/$K67,"")
A68: 7 | B68: Toxoplasmosis and other opportunistic infections readiness | C68: 7.3.6 | D68: P1 | E68: Malnutrition stabilize hypoglycaemia, hypothermia, infection and dehydration; cautious initial feeding for complicated severe acute malnutrition (for example, F-75), then transition to F-100/RUTF for catch-up growth where indicated; continue breastfeeding/age-appropriate feeding; manage micronutrient needs; refer complicated cases and follow age-specific national protocols. | J68: =IF($F68="Yes",1,IF(OR($F68="Partial",$F68="No"),0,"")) | K68: =IF(OR($F68="Yes",$F68="Partial",$F68="No"),1,0) -> 0 | L68: =IF(AND($D68="P1",OR($F68="Partial",$F68="No")),"P1 gap",IF(OR($F68="Partial",$F68="No"),"Gap","")) | M68: =IF($D68="P1",30,IF($D68="P2",90,IF($D68="P3",180,""))) -> 30 | N68: =IF(OR($F68="Partial",$F68="No"),IF(Facility_Profile!$B$7="","",Facility_Profile!$B$7+$M68),"") | O68: =IF($F68="","Missing response",IF(OR($F68="Yes",$F68="Partial",$F68="No",$F68="N/A"),"OK","Check response")) -> Missing response | P68: =IF(OR($F68="Partial",$F68="No"),COUNTIF($F$3:$F68,"Partial")+COUNTIF($F$3:$F68,"No"),"") | Q68: =IFERROR($J68/$K68,"")
A69: 7 | B69: Toxoplasmosis and other opportunistic infections readiness | C69: 7.4 | D69: P1 | E69: Essential medicines, supplies, nutrition commodities and supportive-care inputs are available on site or through a documented referral or resupply pathway for: | F69: =IF(COUNTIF($F$70:$F$75,"Yes")+COUNTIF($F$70:$F$75,"Partial")+COUNTIF($F$70:$F$75,"No")+COUNTIF($F$70:$F$75,"N/A")<6,"Incomplete - complete 6 OI lines",IF($K69=0,"All six marked N/A",$J69&"/"&$K69&" ready")) -> Incomplete - complete 6 OI lines | G69: Complete the six condition-specific scoring lines immediately below. The parent total is calculated automatically and is not scored again. | J69: =SUM($J$70:$J$75) -> 0 | K69: =SUM($K$70:$K$75) -> 0 | L69: =IF(COUNTIF($F$70:$F$75,"Partial")+COUNTIF($F$70:$F$75,"No")>0,"See sub-item gap(s)","") | M69: =IF($D69="P1",30,IF($D69="P2",90,IF($D69="P3",180,""))) -> 30 | N69: =IF(COUNT($N$70:$N$75)=0,"",MIN($N$70:$N$75)) | O69: ="Parent summary - not scored separately" -> Parent summary - not scored separately | P69: ="" | Q69: =IFERROR($J69/$K69,"")
A70: 7 | B70: Toxoplasmosis and other opportunistic infections readiness | C70: 7.4.1 | D70: P1 | E70: Toxoplasmosis co-trimoxazole and/or pyrimethamine, sulfadiazine and folinic acid where used); anticonvulsant and emergency-stabilization supplies; IV access/fluids as indicated | J70: =IF($F70="Yes",1,IF(OR($F70="Partial",$F70="No"),0,"")) | K70: =IF(OR($F70="Yes",$F70="Partial",$F70="No"),1,0) -> 0 | L70: =IF(AND($D70="P1",OR($F70="Partial",$F70="No")),"P1 gap",IF(OR($F70="Partial",$F70="No"),"Gap","")) | M70: =IF($D70="P1",30,IF($D70="P2",90,IF($D70="P3",180,""))) -> 30 | N70: =IF(OR($F70="Partial",$F70="No"),IF(Facility_Profile!$B$7="","",Facility_Profile!$B$7+$M70),"") | O70: =IF($F70="","Missing response",IF(OR($F70="Yes",$F70="Partial",$F70="No",$F70="N/A"),"OK","Check response")) -> Missing response | P70: =IF(OR($F70="Partial",$F70="No"),COUNTIF($F$3:$F70,"Partial")+COUNTIF($F$3:$F70,"No"),"") | Q70: =IFERROR($J70/$K70,"")
A71: 7 | B71: Toxoplasmosis and other opportunistic infections readiness | C71: 7.4.2 | D71: P1 | E71: Pneumocystis pneumonia co-trimoxazole (oral and parenteral where used); reliable oxygen source and delivery devices; pulse oximeter; corticosteroid for severe disease per protocol; IV access/fluids; chest X-ray and respiratory-specimen collection materials; PPE/biosafety supplies; and reliable referral transport. | J71: =IF($F71="Yes",1,IF(OR($F71="Partial",$F71="No"),0,"")) | K71: =IF(OR($F71="Yes",$F71="Partial",$F71="No"),1,0) -> 0 | L71: =IF(AND($D71="P1",OR($F71="Partial",$F71="No")),"P1 gap",IF(OR($F71="Partial",$F71="No"),"Gap","")) | M71: =IF($D71="P1",30,IF($D71="P2",90,IF($D71="P3",180,""))) -> 30 | N71: =IF(OR($F71="Partial",$F71="No"),IF(Facility_Profile!$B$7="","",Facility_Profile!$B$7+$M71),"") | O71: =IF($F71="","Missing response",IF(OR($F71="Yes",$F71="Partial",$F71="No",$F71="N/A"),"OK","Check response")) -> Missing response | P71: =IF(OR($F71="Partial",$F71="No"),COUNTIF($F$3:$F71,"Partial")+COUNTIF($F$3:$F71,"No"),"") | Q71: =IFERROR($J71/$K71,"")
A72: 7 | B72: Toxoplasmosis and other opportunistic infections readiness | C72: 7.4.3 | D72: P1 | E72: Histoplasmosis liposomal amphotericin B and itraconazole; IV infusion supplies; renal/electrolyte/liver monitoring; hydration and adverse-event medicines; and documented specialist/inpatient referral. | J72: =IF($F72="Yes",1,IF(OR($F72="Partial",$F72="No"),0,"")) | K72: =IF(OR($F72="Yes",$F72="Partial",$F72="No"),1,0) -> 0 | L72: =IF(AND($D72="P1",OR($F72="Partial",$F72="No")),"P1 gap",IF(OR($F72="Partial",$F72="No"),"Gap","")) | M72: =IF($D72="P1",30,IF($D72="P2",90,IF($D72="P3",180,""))) -> 30 | N72: =IF(OR($F72="Partial",$F72="No"),IF(Facility_Profile!$B$7="","",Facility_Profile!$B$7+$M72),"") | O72: =IF($F72="","Missing response",IF(OR($F72="Yes",$F72="Partial",$F72="No",$F72="N/A"),"OK","Check response")) -> Missing response | P72: =IF(OR($F72="Partial",$F72="No"),COUNTIF($F$3:$F72,"Partial")+COUNTIF($F$3:$F72,"No"),"") | Q72: =IFERROR($J72/$K72,"")
...

Sheet Readiness_Dashboard
A1: AHD Site Readiness Dashboard
A2: Automatic scoring: Ready units / applicable units. Domain 7 parent rows summarize the six embedded OI lines and are excluded from scoring. Dashboard visuals update automatically as the Checklist is completed.
A4: Metric | B4: Value | C4: Definition | E4: Performance band | F4: Threshold / rule | G4: Interpretation | H4: Color
A5: Overall readiness % | B5: =IFERROR($D$32/$I$32,"") -> 0.5 | C5: Total ready units ÷ total applicable units | E5: Ready | F5: 90–100%, complete, and no unresolved P1 gaps | G5: High readiness; maintain and monitor | H5: Green
A6: Applicable units assessed | B6: =$I$32 -> 2 | C6: Yes + Partial + No; maximum equals the total scorable units (currently 141) | E6: Substantially ready | F6: 80–89.9%, complete, and no unresolved P1 gaps | G6: Targeted improvements required | H6: Yellow
A7: Data completeness % | B7: =IFERROR(($C$32-$H$32)/$C$32,"") -> 0.014184397 | C7: (Total scorable units − missing responses) ÷ total scorable units | E7: Partially ready | F7: 60–79.9%, complete, and no unresolved P1 gaps | G7: Improvement plan and follow-up required | H7: Amber
A8: P1 gaps | B8: =$K$32 -> 1 | C8: P1 sub/items marked Partial or No | E8: Critical readiness gap | F8: <60% or any unresolved P1 gap | G8: Urgent corrective action required | H8: Red
A9: All gaps | B9: =$E$32+$F$32 -> 1 | C9: All Partial and No findings | E9: Incomplete / no data | F9: Missing responses, failed unit check, or no denominator | G9: Complete or correct the assessment before interpretation | H9: Gray
A10: Missing responses | B10: =$H$32 -> 139 | C10: Blank responses requiring completion
A11: N/A units | B11: =$G$32 -> 0 | C11: Completed but excluded from readiness denominator
A12: Readiness status | B12: =IF($B$10>0,"Incomplete - complete all responses",IF($B$6=0,"No applicable items",IF($B$8>0,"Critical - resolve P1 gap(s)",IF($B$5>=0.9,"Ready",IF($B$5>=0.8,"Substantially ready",IF($B$5>=0.6,"Partially ready","Critical readiness gap")))))) -> Incomplete - complete all responses | C12: Requires complete data and no unresolved P1 gaps
A15: Domain # | B15: Domain | C15: Assessment units | D15: Yes | E15: Partial | F15: No | G15: N/A | H15: Missing | I15: Applicable assessed | J15: Readiness % | K15: P1 gaps | L15: P2/P3 gaps | M15: Performance status | N15: Priority actions / comments | AA15: Domain | AB15: Readiness %
A16: 1 | B16: Governance, service model and accountability | C16: =COUNTIFS(Checklist!$A$3:$A$149,$A16,Checklist!$O$3:$O$149,"<>Parent summary - not scored separately") -> 6 | D16: =COUNTIFS(Checklist!$A$3:$A$149,$A16,Checklist!$F$3:$F$149,"Yes",Checklist!$O$3:$O$149,"<>Parent summary - not scored separately") -> 0 | E16: =COUNTIFS(Checklist!$A$3:$A$149,$A16,Checklist!$F$3:$F$149,"Partial",Checklist!$O$3:$O$149,"<>Parent summary - not scored separately") -> 0 | F16: =COUNTIFS(Checklist!$A$3:$A$149,$A16,Checklist!$F$3:$F$149,"No",Checklist!$O$3:$O$149,"<>Parent summary - not scored separately") -> 0 | G16: =COUNTIFS(Checklist!$A$3:$A$149,$A16,Checklist!$F$3:$F$149,"N/A",Checklist!$O$3:$O$149,"<>Parent summary - not scored separately") -> 0 | H16: =C16-SUM(D16:G16) -> 6 | I16: =SUM(D16:F16) -> 0 | J16: =IFERROR(D16/I16,"") | K16: =COUNTIFS(Checklist!$A$3:$A$149,$A16,Checklist!$D$3:$D$149,"P1",Checklist!$F$3:$F$149,"Partial",Checklist!$O$3:$O$149,"<>Parent summary - not scored separately")+COUNTIFS(Checklist!$A$3:$A$149,$A16,Checklist!$D$3:$D$149,"P1",Checklist!$F$3:$F$149,"No",Checklist!$O$3:$O$149,"<>Parent summary - not scored separately") -> 0 | L16: =COUNTIFS(Checklist!$A$3:$A$149,$A16,Checklist!$D$3:$D$149,"P2",Checklist!$F$3:$F$149,"Partial",Checklist!$O$3:$O$149,"<>Parent summary - not scored separately")+COUNTIFS(Checklist!$A$3:$A$149,$A16,Checklist!$D$3:$D$149,"P2",Checklist!$F$3:$F$149,"No",Checklist!$O$3:$O$149,"<>Parent summary - not scored separately")+COUNTIFS(Checklist!$A$3:$A$149,$A16,Checklist!$D$3:$D$149,"P3",Checklist!$F$3:$F$149,"Partial",Checklist!$O$3:$O$149,"<>Parent summary - not scored separately")+COUNTIFS(Checklist!$A$3:$A$149,$A16,Checklist!$D$3:$D$149,"P3",Checklist!$F$3:$F$149,"No",Checklist!$O$3:$O$149,"<>Parent summary - not scored separately") -> 0 | M16: =IF(H16>0,"Incomplete",IF(I16=0,"No applicable items",IF(K16>0,"Critical - P1 gap(s)",IF(J16>=0.9,"Ready",IF(J16>=0.8,"Substantially ready",IF(J16>=0.6,"Partially ready","Critical readiness gap")))))) -> Incomplete | AA16: D1 Governance & accountability | AB16: =IF($I16=0,"",$J16)
A17: 2 | B17: Screening, early detection and identification of clients with AHD | C17: =COUNTIFS(Checklist!$A$3:$A$149,$A17,Checklist!$O$3:$O$149,"<>Parent summary - not scored separately") -> 7 | D17: =COUNTIFS(Checklist!$A$3:$A$149,$A17,Checklist!$F$3:$F$149,"Yes",Checklist!$O$3:$O$149,"<>Parent summary - not scored separately") -> 0 | E17: =COUNTIFS(Checklist!$A$3:$A$149,$A17,Checklist!$F$3:$F$149,"Partial",Checklist!$O$3:$O$149,"<>Parent summary - not scored separately") -> 0 | F17: =COUNTIFS(Checklist!$A$3:$A$149,$A17,Checklist!$F$3:$F$149,"No",Checklist!$O$3:$O$149,"<>Parent summary - not scored separately") -> 0 | G17: =COUNTIFS(Checklist!$A$3:$A$149,$A17,Checklist!$F$3:$F$149,"N/A",Checklist!$O$3:$O$149,"<>Parent summary - not scored separately") -> 0 | H17: =C17-SUM(D17:G17) -> 7 | I17: =SUM(D17:F17) -> 0 | J17: =IFERROR(D17/I17,"") | K17: =COUNTIFS(Checklist!$A$3:$A$149,$A17,Checklist!$D$3:$D$149,"P1",Checklist!$F$3:$F$149,"Partial",Checklist!$O$3:$O$149,"<>Parent summary - not scored separately")+COUNTIFS(Checklist!$A$3:$A$149,$A17,Checklist!$D$3:$D$149,"P1",Checklist!$F$3:$F$149,"No",Checklist!$O$3:$O$149,"<>Parent summary - not scored separately") -> 0 | L17: =COUNTIFS(Checklist!$A$3:$A$149,$A17,Checklist!$D$3:$D$149,"P2",Checklist!$F$3:$F$149,"Partial",Checklist!$O$3:$O$149,"<>Parent summary - not scored separately")+COUNTIFS(Checklist!$A$3:$A$149,$A17,Checklist!$D$3:$D$149,"P2",Checklist!$F$3:$F$149,"No",Checklist!$O$3:$O$149,"<>Parent summary - not scored separately")+COUNTIFS(Checklist!$A$3:$A$149,$A17,Checklist!$D$3:$D$149,"P3",Checklist!$F$3:$F$149,"Partial",Checklist!$O$3:$O$149,"<>Parent summary - not scored separately")+COUNTIFS(Checklist!$A$3:$A$149,$A17,Checklist!$D$3:$D$149,"P3",Checklist!$F$3:$F$149,"No",Checklist!$O$3:$O$149,"<>Parent summary - not scored separately") -> 0 | M17: =IF(H17>0,"Incomplete",IF(I17=0,"No applicable items",IF(K17>0,"Critical - P1 gap(s)",IF(J17>=0.9,"Ready",IF(J17>=0.8,"Substantially ready",IF(J17>=0.6,"Partially ready","Critical readiness gap")))))) -> Incomplete | AA17: D2 AHD screening & identification | AB17: =IF($I17=0,"",$J17)
A18: 3 | B18: Triage, danger signs, emergency stabilization and referral | C18: =COUNTIFS(Checklist!$A$3:$A$149,$A18,Checklist!$O$3:$O$149,"<>Parent summary - not scored separately") -> 7 | D18: =COUNTIFS(Checklist!$A$3:$A$149,$A18,Checklist!$F$3:$F$149,"Yes",Checklist!$O$3:$O$149,"<>Parent summary - not scored separately") -> 0 | E18: =COUNTIFS(Checklist!$A$3:$A$149,$A18,Checklist!$F$3:$F$149,"Partial",Checklist!$O$3:$O$149,"<>Parent summary - not scored separately") -> 0 | F18: =COUNTIFS(Checklist!$A$3:$A$149,$A18,Checklist!$F$3:$F$149,"No",Checklist!$O$3:$O$149,"<>Parent summary - not scored separately") -> 0 | G18: =COUNTIFS(Checklist!$A$3:$A$149,$A18,Checklist!$F$3:$F$149,"N/A",Checklist!$O$3:$O$149,"<>Parent summary - not scored separately") -> 0 | H18: =C18-SUM(D18:G18) -> 7 | I18: =SUM(D18:F18) -> 0 | J18: =IFERROR(D18/I18,"") | K18: =COUNTIFS(Checklist!$A$3:$A$149,$A18,Checklist!$D$3:$D$149,"P1",Checklist!$F$3:$F$149,"Partial",Checklist!$O$3:$O$149,"<>Parent summary - not scored separately")+COUNTIFS(Checklist!$A$3:$A$149,$A18,Checklist!$D$3:$D$149,"P1",Checklist!$F$3:$F$149,"No",Checklist!$O$3:$O$149,"<>Parent summary - not scored separately") -> 0 | L18: =COUNTIFS(Checklist!$A$3:$A$149,$A18,Checklist!$D$3:$D$149,"P2",Checklist!$F$3:$F$149,"Partial",Checklist!$O$3:$O$149,"<>Parent summary - not scored separately")+COUNTIFS(Checklist!$A$3:$A$149,$A18,Checklist!$D$3:$D$149,"P2",Checklist!$F$3:$F$149,"No",Checklist!$O$3:$O$149,"<>Parent summary - not scored separately")+COUNTIFS(Checklist!$A$3:$A$149,$A18,Checklist!$D$3:$D$149,"P3",Checklist!$F$3:$F$149,"Partial",Checklist!$O$3:$O$149,"<>Parent summary - not scored separately")+COUNTIFS(Checklist!$A$3:$A$149,$A18,Checklist!$D$3:$D$149,"P3",Checklist!$F$3:$F$149,"No",Checklist!$O$3:$O$149,"<>Parent summary - not scored separately") -> 0 | M18: =IF(H18>0,"Incomplete",IF(I18=0,"No applicable items",IF(K18>0,"Critical - P1 gap(s)",IF(J18>=0.9,"Ready",IF(J18>=0.8,"Substantially ready",IF(J18>=0.6,"Partially ready","Critical readiness gap")))))) -> Incomplete | AA18: D3 Triage, stabilization & referral | AB18: =IF($I18=0,"",$J18)
A19: 4 | B19: CD4, laboratory and diagnostic network readiness | C19: =COUNTIFS(Checklist!$A$3:$A$149,$A19,Checklist!$O$3:$O$149,"<>Parent summary - not scored separately") -> 7 | D19: =COUNTIFS(Checklist!$A$3:$A$149,$A19,Checklist!$F$3:$F$149,"Yes",Checklist!$O$3:$O$149,"<>Parent summary - not scored separately") -> 0 | E19: =COUNTIFS(Checklist!$A$3:$A$149,$A19,Checklist!$F$3:$F$149,"Partial",Checklist!$O$3:$O$149,"<>Parent summary - not scored separately") -> 0 | F19: =COUNTIFS(Checklist!$A$3:$A$149,$A19,Checklist!$F$3:$F$149,"No",Checklist!$O$3:$O$149,"<>Parent summary - not scored separately") -> 0 | G19: =COUNTIFS(Checklist!$A$3:$A$149,$A19,Checklist!$F$3:$F$149,"N/A",Checklist!$O$3:$O$149,"<>Parent summary - not scored separately") -> 0 | H19: =C19-SUM(D19:G19) -> 7 | I19: =SUM(D19:F19) -> 0 | J19: =IFERROR(D19/I19,"") | K19: =COUNTIFS(Checklist!$A$3:$A$149,$A19,Checklist!$D$3:$D$149,"P1",Checklist!$F$3:$F$149,"Partial",Checklist!$O$3:$O$149,"<>Parent summary - not scored separately")+COUNTIFS(Checklist!$A$3:$A$149,$A19,Checklist!$D$3:$D$149,"P1",Checklist!$F$3:$F$149,"No",Checklist!$O$3:$O$149,"<>Parent summary - not scored separately") -> 0 | L19: =COUNTIFS(Checklist!$A$3:$A$149,$A19,Checklist!$D$3:$D$149,"P2",Checklist!$F$3:$F$149,"Partial",Checklist!$O$3:$O$149,"<>Parent summary - not scored separately")+COUNTIFS(Checklist!$A$3:$A$149,$A19,Checklist!$D$3:$D$149,"P2",Checklist!$F$3:$F$149,"No",Checklist!$O$3:$O$149,"<>Parent summary - not scored separately")+COUNTIFS(Checklist!$A$3:$A$149,$A19,Checklist!$D$3:$D$149,"P3",Checklist!$F$3:$F$149,"Partial",Checklist!$O$3:$O$149,"<>Parent summary - not scored separately")+COUNTIFS(Checklist!$A$3:$A$149,$A19,Checklist!$D$3:$D$149,"P3",Checklist!$F$3:$F$149,"No",Checklist!$O$3:$O$149,"<>Parent summary - not scored separately") -> 0 | M19: =IF(H19>0,"Incomplete",IF(I19=0,"No applicable items",IF(K19>0,"Critical - P1 gap(s)",IF(J19>=0.9,"Ready",IF(J19>=0.8,"Substantially ready",IF(J19>=0.6,"Partially ready","Critical readiness gap")))))) -> Incomplete | AA19: D4 CD4, laboratory & diagnostics | AB19: =IF($I19=0,"",$J19)
